Workbook

Sheet Instructions
A1: MS Excel Practical Exam
A2: Total Questions: 30
A3: Difficulty Level: Medium
A4: Syllabus: Formulas, Logical Functions, Lookups, INDEX-MATCH, Pivot Tables & Charts, Data Analysis
A5: Attempt all questions using appropriate Excel tools/functions.

Sheet Sales_Data
A1: Order_ID | B1: Region | C1: Salesperson | D1: Product | E1: Quantity | F1: Unit_Price | G1: Sales_Date
A2: 301 | B2: North | C2: Amit | D2: Laptop | E2: 2 | F2: 45000 | G2: 05-01-2025
A3: 302 | B3: South | C3: Riya | D3: Mobile | E3: 5 | F3: 15000 | G3: 07-01-2025
A4: 303 | B4: East | C4: Kunal | D4: Tablet | E4: 3 | F4: 18000 | G4: 10-01-2025
A5: 304 | B5: West | C5: Neha | D5: Laptop | E5: 1 | F5: 45000 | G5: 12-01-2025
A6: 305 | B6: North | C6: Amit | D6: Mobile | E6: 4 | F6: 15000 | G6: 15-01-2025
A7: 306 | B7: South | C7: Riya | D7: Laptop | E7: 2 | F7: 45000 | G7: 18-01-2025

Sheet Product_Master
A1: Product | B1: Category | C1: GST_%
A2: Laptop | B2: Electronics | C2: 18
A3: Mobile | B3: Electronics | C3: 12
A4: Tablet | B4: Electronics | C4: 12

Sheet Student_Marks
A1: Student_ID | B1: Name | C1: Maths | D1: Statistics | E1: Excel | F1: Attendance_%
A2: 1 | B2: Rahul | C2: 78 | D2: 82 | E2: 85 | F2: 92
A3: 2 | B3: Sneha | C3: 88 | D3: 91 | E3: 90 | F3: 96
A4: 3 | B4: Arjun | C4: 65 | D4: 70 | E4: 72 | F4: 85
A5: 4 | B5: Pooja | C5: 92 | D5: 89 | E5: 94 | F5: 98
A6: 5 | B6: Vikas | C6: 55 | D6: 60 | E6: 58 | F6: 80

Sheet Questions
A1: 1. Calculate Total Sales for each order (Quantity × Unit_Price). | J1: 2
A2: 2. Calculate GST Amount using VLOOKUP from Product_Master. | J2: 2
A3: 3. Find Final Amount payable (Total Sales + GST). | J3: 2
A4: 4. Find Grand Total of Final Amount. | J4: 2
A5: 5. Count total number of orders using COUNTA. | J5: 2
A6: 6. Find Region-wise total sales using SUMIF. | J6: 2
A7: 7. Use IF to classify Quantity as High (>3) or Low (<=3). | J7: 2
A8: 8. Find the maximum and minimum Final Amount. | J8: 2
A9: 9. Extract month name from Sales_Date. | J9: 2
A10: 10. Sort Sales_Data by Final Amount (Descending). | J10: 2
A11: 11. Use INDEX-MATCH to fetch Product Category. | J11: 2
A12: 12. Calculate average marks of each student. | J12: 2
... A30: 30. Protect the Student_Marks sheet. | J30: 2
J32: =SUM(J1:J30) -> 60

Sheet Answer
A1: Q.1
A3: Product | B3: Quantity | C3: Unit_Price | D3: Total sale
A4: Laptop | B4: 2 | C4: 45000 | D4: =B4*C4 -> 90000
A5: Mobile | B5: 5 | C5: 15000 | D5: =B5*C5 -> 75000
A6: Tablet | B6: 3 | C6: 18000 | D6: =B6*C6 -> 54000
A7: Laptop | B7: 1 | C7: 45000 | D7: =B7*C7 -> 45000
A8: Mobile | B8: 4 | C8: 15000 | D8: =B8*C8 -> 60000
A9: Laptop | B9: 2 | C9: 45000 | D9: =B9*C9 -> 90000
A11: Q.2
A13: Product | B13: Total sale | C13: GST_% | D13: GST
A14: Laptop | B14: 90000 | C14: 18 | D14: =B14 * VLOOKUP(A14,A13:C19,3,0)/100 -> 16200
A15: Mobile | B15: 75000 | C15: 12 | D15: =B15 * VLOOKUP(A15,A14:C20,3,0)/100 -> 9000
A16: Tablet | B16: 54000 | C16: 12 | D16: =B16 * VLOOKUP(A16,A15:C21,3,0)/100 -> 6480
A17: Laptop | B17: 45000 | C17: 18 | D17: =B17 * VLOOKUP(A17,A16:C22,3,0)/100 -> 8100
A18: Mobile | B18: 60000 | C18: 12 | D18: =B18 * VLOOKUP(A18,A17:C23,3,0)/100 -> 7200
A19: Laptop | B19: 90000 | C19: 18 | D19: =B19 * VLOOKUP(A19,A18:C24,3,0)/100 -> 16200
A22: Q.3
A24: Product | B24: Total sale | C24: GST | D24: Total paybel
A25: Laptop | B25: 90000 | C25: 16200 | D25: =SUM(B25,C25) -> 106200
A26: Mobile | B26: 75000 | C26: 9000 | D26: =SUM(B26,C26) -> 84000
A27: Tablet | B27: 54000 | C27: 6480 | D27: =SUM(B27,C27) -> 60480
A28: Laptop | B28: 45000 | C28: 8100 | D28: =SUM(B28,C28) -> 53100
A29: Mobile | B29: 60000 | C29: 7200 | D29: =SUM(B29,C29) -> 67200
A30: Laptop | B30: 90000 | C30: 16200 | D30: =SUM(B30,C30) -> 106200
A32: Q.4
A34: Product | B34: Total paybel
A35: Laptop | B35: 106200
A36: Mobile | B36: 84000
A37: Tablet | B37: 60480
A38: Laptop | B38: 53100
A39: Mobile | B39: 67200
A40: Laptop | B40: 106200
A41: Grand Amt | B41: =SUM(B35:B40) -> 477180
A44: Q.5
A46: Order_ID
A47: 301
A48: 302
A49: 303
A50: 304
A51: 305
...
